<?xml version="1.0" encoding="utf-8"?>
<!-- =================================================================================== -->
<!-- |    This document was autogenerated by xacro from ari.urdf.xacro                 | -->
<!-- |    EDITING THIS FILE BY HAND IS NOT RECOMMENDED                                 | -->
<!-- =================================================================================== -->
<!--
  Copyright (c) 2019, PAL Robotics, S.L.
  All rights reserved.

  This work is licensed under the Creative Commons Attribution-NonCommercial-NoDerivs 3.0 Unported License.
  To view a copy of this license, visit http://creativecommons.org/licenses/by-nc-nd/3.0/ or send a letter to
  Creative Commons, 444 Castro Street, Suite 900, Mountain View, California, 94041, USA.
-->
<robot name="ari">
  <!-- RGBD Laser Link -->
  <joint name="rgbd_laser_joint" type="fixed">
    <parent link="base_link"/>
    <child link="rgbd_laser_link"/>
    <origin rpy="0 0 0" xyz="-1.1 0 0"/>
  </joint>
  <link name="rgbd_laser_link">
    <inertial>
      <origin rpy="0 0 0" xyz="0 0 0"/>
      <mass value="0.0001"/>
      <inertia ixx="0.0001" ixy="0" ixz="0" iyy="0.0001" iyz="0" izz="0.0001"/>
    </inertial>
  </link>
  <joint name="back_led_link" type="fixed">
    <origin rpy="0.0 0.2 1.57" xyz="-0.12 0.0 -0.08"/>
    <child link="back_led_frame"/>
    <parent link="head_1_link"/>
  </joint>
  <link name="back_led_frame">
    <inertial>
      <origin rpy="0 0 0" xyz="0 0 0"/>
      <mass value="0.001"/>
      <!-- matrix below must not be zero, or Gazebo won't load -->
      <inertia ixx="0.0001" ixy="0.0" ixz="0.0" iyy="0.000001" iyz="0.0" izz="0.0001"/>
    </inertial>
  </link>
  <link name="base_laser_link" type="laser">
    <inertial>
      <origin rpy="0 0 0" xyz="-0.02559000000 -0.00056000000 -0.05732000000"/>
      <mass value="0.28922000000"/>
      <inertia ixx="0.00002628919" ixy="0.00000024298" ixz="-0.00000368129" iyy="0.00003374542" iyz="-0.00000001330" izz="0.00005832599"/>
    </inertial>
    <visual>
      <origin rpy="0 0 0" xyz="0 0 0"/>
      <geometry>
        <mesh filename="package://ari_description/meshes/sensors/sick_tim551.stl"/>
      </geometry>
      <material name="DarkGrey"/>
    </visual>
  </link>
  <joint name="base_laser_joint" type="fixed">
    <axis xyz="0 1 0"/>
    <origin rpy="0 018 0" xyz="0.0 0.0 0.0"/>
    <parent link="base_link"/>
    <child link="base_laser_link"/>
  </joint>
  <gazebo reference="base_laser_link">
    <sensor name="base_laser" type="ray">
      <pose>0 0 0 0 0 0</pose>
      <update_rate>10</update_rate>
      <visualize>true</visualize>
      <ray>
        <scan>
          <horizontal>
            <!-- 818 (270/0.33) steps in 270deg fov -->
            <samples>666.518518519</samples>
            <resolution>1</resolution>
            <!-- not the sensor resolution; just 1 -->
            <min_angle>-1.91986217719</min_angle>
            <max_angle>1.91986217719</max_angle>
          </horizontal>
        </scan>
        <range>
          <min>0.05</min>
          <max>25.0</max>
          <resolution>0.001</resolution>
        </range>
      </ray>
      <plugin filename="libgazebo_ros_laser.so" name="gazebo_ros_sick_laser">
        <gaussianNoise>0.06</gaussianNoise>
        <alwaysOn>true</alwaysOn>
        <updateRate>10</updateRate>
        <topicName>scan_raw</topicName>
        <frameName>base_laser_link</frameName>
      </plugin>
    </sensor>
    <material>Gazebo/DarkGrey</material>
  </gazebo>
  <link name="base_sonar_03_link">
    <inertial>
      <origin rpy="0 0 0" xyz="0 0 0"/>
      <mass value="0.001"/>
      <inertia ixx="0.000001" ixy="0" ixz="0" iyy="0.000001" iyz="0" izz="0.000001"/>
    </inertial>
    <visual>
      <origin rpy="0 0 0" xyz="0 0 0"/>
      <geometry>
        <mesh filename="package://ari_description/meshes/sensors/srf05.stl"/>
      </geometry>
      <material name="DarkGrey"/>
    </visual>
  </link>
  <joint name="base_sonar_03_joint" type="fixed">
    <origin rpy="0 0 2.35619449019" xyz="-0.183 0.183 0.173"/>
    <axis xyz="0 0 1"/>
    <parent link="base_link"/>
    <child link="base_sonar_03_link"/>
  </joint>
  <gazebo reference="base_sonar_03_link">
    <sensor name="base_sonar_03" type="ray">
      <pose>0 0 0 0 0 0</pose>
      <update_rate>5</update_rate>
      <visualize>false</visualize>
      <ray>
        <scan>
          <horizontal>
            <samples>5</samples>
            <resolution>1</resolution>
            <min_angle>-0.25</min_angle>
            <max_angle>0.25</max_angle>
          </horizontal>
          <vertical>
            <samples>5</samples>
            <resolution>1</resolution>
            <min_angle>-0.25</min_angle>
            <max_angle>0.25</max_angle>
          </vertical>
        </scan>
        <range>
          <min>0.02</min>
          <max>1.0</max>
          <resolution>0.01</resolution>
        </range>
      </ray>
      <plugin filename="libgazebo_ros_range.so" name="gazebo_ros_range">
        <gaussianNoise>0.005</gaussianNoise>
        <alwaysOn>true</alwaysOn>
        <updateRate>5</updateRate>
        <topicName>sonar_base</topicName>
        <frameName>base_sonar_03_link</frameName>
        <minRange>0.02</minRange>
        <maxRange>1.0</maxRange>
        <fov>0.5</fov>
        <radiation>ultrasound</radiation>
      </plugin>
    </sensor>
    <material>Gazebo/DarkGrey</material>
  </gazebo>
  <link name="base_sonar_02_link">
    <inertial>
      <origin rpy="0 0 0" xyz="0 0 0"/>
      <mass value="0.001"/>
      <inertia ixx="0.000001" ixy="0" ixz="0" iyy="0.000001" iyz="0" izz="0.000001"/>
    </inertial>
    <visual>
      <origin rpy="0 0 0" xyz="0 0 0"/>
      <geometry>
        <mesh filename="package://ari_description/meshes/sensors/srf05.stl"/>
      </geometry>
      <material name="DarkGrey"/>
    </visual>
  </link>
  <joint name="base_sonar_02_joint" type="fixed">
    <origin rpy="0 0 3.14159265359" xyz="-0.259 0.0 0.173"/>
    <axis xyz="0 0 1"/>
    <parent link="base_link"/>
    <child link="base_sonar_02_link"/>
  </joint>
  <gazebo reference="base_sonar_02_link">
    <sensor name="base_sonar_02" type="ray">
      <pose>0 0 0 0 0 0</pose>
      <update_rate>5</update_rate>
      <visualize>false</visualize>
      <ray>
        <scan>
          <horizontal>
            <samples>5</samples>
            <resolution>1</resolution>
            <min_angle>-0.25</min_angle>
            <max_angle>0.25</max_angle>
          </horizontal>
          <vertical>
            <samples>5</samples>
            <resolution>1</resolution>
            <min_angle>-0.25</min_angle>
            <max_angle>0.25</max_angle>
          </vertical>
        </scan>
        <range>
          <min>0.02</min>
          <max>1.0</max>
          <resolution>0.01</resolution>
        </range>
      </ray>
      <plugin filename="libgazebo_ros_range.so" name="gazebo_ros_range">
        <gaussianNoise>0.005</gaussianNoise>
        <alwaysOn>true</alwaysOn>
        <updateRate>5</updateRate>
        <topicName>sonar_base</topicName>
        <frameName>base_sonar_02_link</frameName>
        <minRange>0.02</minRange>
        <maxRange>1.0</maxRange>
        <fov>0.5</fov>
        <radiation>ultrasound</radiation>
      </plugin>
    </sensor>
    <material>Gazebo/DarkGrey</material>
  </gazebo>
  <link name="base_sonar_01_link">
    <inertial>
      <origin rpy="0 0 0" xyz="0 0 0"/>
      <mass value="0.001"/>
      <inertia ixx="0.000001" ixy="0" ixz="0" iyy="0.000001" iyz="0" izz="0.000001"/>
    </inertial>
    <visual>
      <origin rpy="0 0 0" xyz="0 0 0"/>
      <geometry>
        <mesh filename="package://ari_description/meshes/sensors/srf05.stl"/>
      </geometry>
      <material name="DarkGrey"/>
    </visual>
  </link>
  <joint name="base_sonar_01_joint" type="fixed">
    <origin rpy="0 0 3.92699081699" xyz="-0.183 -0.183 0.173"/>
    <axis xyz="0 0 1"/>
    <parent link="base_link"/>
    <child link="base_sonar_01_link"/>
  </joint>
  <gazebo reference="base_sonar_01_link">
    <sensor name="base_sonar_01" type="ray">
      <pose>0 0 0 0 0 0</pose>
      <update_rate>5</update_rate>
      <visualize>false</visualize>
      <ray>
        <scan>
          <horizontal>
            <samples>5</samples>
            <resolution>1</resolution>
            <min_angle>-0.25</min_angle>
            <max_angle>0.25</max_angle>
          </horizontal>
          <vertical>
            <samples>5</samples>
            <resolution>1</resolution>
            <min_angle>-0.25</min_angle>
            <max_angle>0.25</max_angle>
          </vertical>
        </scan>
        <range>
          <min>0.02</min>
          <max>1.0</max>
          <resolution>0.01</resolution>
        </range>
      </ray>
      <plugin filename="libgazebo_ros_range.so" name="gazebo_ros_range">
        <gaussianNoise>0.005</gaussianNoise>
        <alwaysOn>true</alwaysOn>
        <updateRate>5</updateRate>
        <topicName>sonar_base</topicName>
        <frameName>base_sonar_01_link</frameName>
        <minRange>0.02</minRange>
        <maxRange>1.0</maxRange>
        <fov>0.5</fov>
        <radiation>ultrasound</radiation>
      </plugin>
    </sensor>
    <material>Gazebo/DarkGrey</material>
  </gazebo>
  <!-- Base -->
  <link name="base_link">
    <inertial>
      <origin rpy="0 0 0" xyz="-0.18664 -0.0032701 0.2776"/>
      <mass value="43.407"/>
      <inertia ixx="0.71785" ixy="-7.1158E-05" ixz="0.054913" iyy="0.74432" iyz="-9.0871E-06" izz="0.45635"/>
    </inertial>
    <visual>
      <origin rpy="0 0 0" xyz="0 0 0"/>
      <geometry>
        <mesh filename="package://ari_description/meshes/base/base.stl"/>
      </geometry>
      <material name="Grey"/>
    </visual>
    <collision>
      <origin rpy="0 0 0" xyz="0 0 0"/>
      <geometry>
        <mesh filename="package://ari_description/meshes/base/base_collision.stl"/>
      </geometry>
      <material name="Grey"/>
    </collision>
  </link>
  <gazebo reference="base_link">
    <material>Gazebo/White</material>
  </gazebo>
  <!-- Base footprint -->
  <link name="base_footprint"/>
  <joint name="base_footprint_joint" type="fixed">
    <origin rpy="0 0 0" xyz="0 0 0.125"/>
    <child link="base_link"/>
    <parent link="base_footprint"/>
  </joint>
  <!-- gazebo parameters are given here for base_link thru base_footprint -->
  <gazebo reference="base_footprint">
    <kp>100000000.0</kp>
    <kd>10.0</kd>
    <mu1>0.1</mu1>
    <mu2>0.1</mu2>
    <fdir1>1 0 0</fdir1>
    <maxVel>10.0</maxVel>
    <minDepth>0.0005</minDepth>
    <laserRetro>0</laserRetro>
  </gazebo>
  <link name="wheel_right_link">
    <inertial>
      <origin rpy="0 0 0" xyz="-5.88525464208667E-06 -7.00561297658359E-05 -0.00222902971508"/>
      <mass value="1.65651"/>
      <inertia ixx="0.00630296404438488" ixy="1.03273612245952E-10" ixz="-7.0841360242e-07" iyy="0.00630218683572781" iyz="-5.36273874221e-08" izz="0.0111537170515009"/>
    </inertial>
    <visual>
      <origin rpy="0 0 0" xyz="0 0 0"/>
      <geometry>
        <mesh filename="package://ari_description/meshes/wheels/wheel_right.stl"/>
      </geometry>
      <material name="White"/>
    </visual>
    <collision>
      <origin rpy="0 0 0" xyz="0 0 0"/>
      <geometry>
        <cylinder length="0.075" radius="0.125"/>
      </geometry>
    </collision>
    <kinematic>0</kinematic>
    <gravity>1</gravity>
  </link>
  <joint name="wheel_right_joint" type="continuous">
    <parent link="base_link"/>
    <child link="wheel_right_link"/>
    <origin rpy="1.57079632679 0 0" xyz="0 -0.22 0"/>
    <axis xyz="0 0 -1"/>
    <limit effort="6.0" velocity="8.0"/>
  </joint>
  <transmission name="wheel_right_trans">
    <type>transmission_interface/SimpleTransmission</type>
    <actuator name="wheel_right_motor">
      <mechanicalReduction>1.0</mechanicalReduction>
    </actuator>
    <joint name="wheel_right_joint">
      <hardwareInterface>hardware_interface/VelocityJointInterface</hardwareInterface>
      <hardwareInterface>hardware_interface/JointStateInterface</hardwareInterface>
    </joint>
  </transmission>
  <!-- Contact model for the wheel surface -->
  <gazebo reference="wheel_right_link">
    <kp>1000000.0</kp>
    <kd>1000.0</kd>
    <mu1>1.0</mu1>
    <mu2>0.1</mu2>
    <!-- Frictionless wheels 0.0-->
    <fdir1>1 0 0</fdir1>
    <maxVel>1.0</maxVel>
    <minDepth>0.00</minDepth>
    <implicitSpringDamper>1</implicitSpringDamper>
    <material>Gazebo/DarkGrey</material>
  </gazebo>
  <link name="wheel_left_link">
    <inertial>
      <origin rpy="0 0 0" xyz="-5.88525464208667E-06 -7.00561297658359E-05 0.00222902971508"/>
      <mass value="1.65651"/>
      <inertia ixx="0.00630296404438488" ixy="1.03273612245952E-10" ixz="7.0841360242e-07" iyy="0.00630218683572781" iyz="5.36273874221e-08" izz="0.0111537170515009"/>
    </inertial>
    <visual>
      <origin rpy="0 0 0" xyz="0 0 0"/>
      <geometry>
        <mesh filename="package://ari_description/meshes/wheels/wheel_left.stl"/>
      </geometry>
      <material name="White"/>
    </visual>
    <collision>
      <origin rpy="0 0 0" xyz="0 0 0"/>
      <geometry>
        <cylinder length="0.075" radius="0.125"/>
      </geometry>
    </collision>
    <kinematic>0</kinematic>
    <gravity>1</gravity>
  </link>
  <joint name="wheel_left_joint" type="continuous">
    <parent link="base_link"/>
    <child link="wheel_left_link"/>
    <origin rpy="1.57079632679 0 0" xyz="0 0.22 0"/>
    <axis xyz="0 0 -1"/>
    <limit effort="6.0" velocity="8.0"/>
  </joint>
  <transmission name="wheel_left_trans">
    <type>transmission_interface/SimpleTransmission</type>
    <actuator name="wheel_left_motor">
      <mechanicalReduction>1.0</mechanicalReduction>
    </actuator>
    <joint name="wheel_left_joint">
      <hardwareInterface>hardware_interface/VelocityJointInterface</hardwareInterface>
      <hardwareInterface>hardware_interface/JointStateInterface</hardwareInterface>
    </joint>
  </transmission>
  <!-- Contact model for the wheel surface -->
  <gazebo reference="wheel_left_link">
    <kp>1000000.0</kp>
    <kd>1000.0</kd>
    <mu1>1.0</mu1>
    <mu2>0.1</mu2>
    <!-- Frictionless wheels 0.0-->
    <fdir1>1 0 0</fdir1>
    <maxVel>1.0</maxVel>
    <minDepth>0.00</minDepth>
    <implicitSpringDamper>1</implicitSpringDamper>
    <material>Gazebo/DarkGrey</material>
  </gazebo>
  <link name="caster_right_link">
    <inertial>
      <origin rpy="0 0 0" xyz="1.4445e-06 0.016213 -0.00019766"/>
      <mass value="0.24242"/>
      <inertia ixx="0.0002099" ixy="-5.5806e-09" ixz="-6.9375E-11" iyy="0.00020239" iyz="-2.6771e-09" izz="0.00025496"/>
    </inertial>
    <visual>
      <origin rpy="0 0 0" xyz="0 0 0"/>
      <geometry>
        <mesh filename="package://ari_description/meshes/wheels/caster_right.stl"/>
      </geometry>
      <material name="Grey"/>
    </visual>
    <collision>
      <origin rpy="0 0 0" xyz="0 0 0"/>
      <geometry>
        <cylinder length="0.055" radius="0.045"/>
      </geometry>
    </collision>
  </link>
  <joint name="caster_right_joint" type="continuous">
    <parent link="base_link"/>
    <child link="caster_right_link"/>
    <origin rpy="1.57079632679 0 0" xyz="-0.455 -0.1025 -0.08"/>
    <axis xyz="0 0 -1"/>
  </joint>
  <!-- Contact model for the caster wheel surface -->
  <!--gazebo reference="caster_${side}_1_link">
      <kp>1000000.0</kp>
      <kd>1000.0</kd>
      <mu1>1.0</mu1>
      <mu2>1.0</mu2>
      <fdir1>0 0 1</fdir1>
      <maxVel>1.0</maxVel>
      <minDepth>0.0</minDepth>
      <implicitSpringDamper>0</implicitSpringDamper>
      <material>Gazebo/DarkGrey</material>
    </gazebo-->
  <gazebo reference="caster_right_link">
    <kp>1000000.0</kp>
    <kd>1000.0</kd>
    <mu1>1.0</mu1>
    <mu2>0.04</mu2>
    <fdir1>1 0 0</fdir1>
    <maxVel>1.0</maxVel>
    <minDepth>0.00</minDepth>
    <implicitSpringDamper>0</implicitSpringDamper>
    <material>Gazebo/DarkGrey</material>
  </gazebo>
  <link name="caster_left_link">
    <inertial>
      <origin rpy="0 0 0" xyz="-1.4445e-06 0.016213 0.00019766"/>
      <mass value="0.24242"/>
      <inertia ixx="0.0002099" ixy="5.5806e-09" ixz="-6.9375E-11" iyy="0.00020239" iyz="2.6771e-09" izz="0.00025496"/>
    </inertial>
    <visual>
      <origin rpy="0 0 0" xyz="0 0 0"/>
      <geometry>
        <mesh filename="package://ari_description/meshes/wheels/caster_left.stl"/>
      </geometry>
      <material name="Grey"/>
    </visual>
    <collision>
      <origin rpy="0 0 0" xyz="0 0 0"/>
      <geometry>
        <cylinder length="0.055" radius="0.045"/>
      </geometry>
    </collision>
  </link>
  <joint name="caster_left_joint" type="continuous">
    <parent link="base_link"/>
    <child link="caster_left_link"/>
    <origin rpy="1.57079632679 0 0" xyz="-0.455 0.1025 -0.08"/>
    <axis xyz="0 0 -1"/>
  </joint>
  <!-- Contact model for the caster wheel surface -->
  <!--gazebo reference="caster_${side}_1_link">
      <kp>1000000.0</kp>
      <kd>1000.0</kd>
      <mu1>1.0</mu1>
      <mu2>1.0</mu2>
      <fdir1>0 0 1</fdir1>
      <maxVel>1.0</maxVel>
      <minDepth>0.0</minDepth>
      <implicitSpringDamper>0</implicitSpringDamper>
      <material>Gazebo/DarkGrey</material>
    </gazebo-->
  <gazebo reference="caster_left_link">
    <kp>1000000.0</kp>
    <kd>1000.0</kd>
    <mu1>1.0</mu1>
    <mu2>0.04</mu2>
    <fdir1>1 0 0</fdir1>
    <maxVel>1.0</maxVel>
    <minDepth>0.00</minDepth>
    <implicitSpringDamper>0</implicitSpringDamper>
    <material>Gazebo/DarkGrey</material>
  </gazebo>
  <gazebo>
    <plugin filename="libgazebo_ros_control.so" name="gazebo_ros_control">
      <ns/>
      <robotSimType>pal_hardware_gazebo/PalHardwareGazebo</robotSimType>
      <robotNamespace/>
      <controlPeriod>0.001</controlPeriod>
    </plugin>
    <plugin filename="libgazebo_ros_p3d.so" name="gazebo_ros_p3d">
      <bodyName>base_footprint</bodyName>
      <topicName>ground_truth_odom</topicName>
      <alwaysOn>true</alwaysOn>
      <updateRate>100.0</updateRate>
    </plugin>
  </gazebo>
  <gazebo>
    <plugin filename="libgazebo_world_odometry.so" name="gazebo_ros_odometry">
      <frameName>base_footprint</frameName>
      <topicName>floating_base_pose_simulated</topicName>
    </plugin>
  </gazebo>
  <material name="Blue">
    <color rgba="0.0 0.0 0.8 1.0"/>
  </material>
  <material name="Green">
    <color rgba="0.0 0.8 0.0 1.0"/>
  </material>
  <material name="Grey">
    <color rgba="0.75294 0.75294 0.75294 1.0"/>
  </material>
  <material name="LightGrey">
    <color rgba="0.9 0.9 0.9 1.0"/>
  </material>
  <material name="DarkGrey">
    <color rgba="0.1 0.1 0.1 1.0"/>
  </material>
  <material name="Red">
    <color rgba="0.8 0.0 0.0 1.0"/>
  </material>
  <material name="White">
    <color rgba="1.0 1.0 1.0 1.0"/>
  </material>
  <material name="Yellow">
    <color rgba="0.96 0.88 0.14 1.0"/>
  </material>
  <!-- Now we can start using the macros included above to define the actual robot -->
  <material name="torso_front_camera_aluminum">
    <color rgba="0.5 0.5 0.5 1"/>
  </material>
  <!-- camera body, with origin at bottom screw mount -->
  <joint name="torso_front_camera_joint" type="fixed">
    <origin rpy="0.0 0.741764932098 0.0" xyz="-0.11249 0.0 0.97052"/>
    <parent link="base_link"/>
    <child link="torso_front_camera_bottom_screw_frame"/>
  </joint>
  <link name="torso_front_camera_bottom_screw_frame"/>
  <joint name="torso_front_camera_link_joint" type="fixed">
    <origin rpy="0 0 0" xyz="0 0.0175 0.0125"/>
    <parent link="torso_front_camera_bottom_screw_frame"/>
    <child link="torso_front_camera_link"/>
  </joint>
  <link name="torso_front_camera_link">
    <visual>
      <origin rpy="1.57079632679 0 1.57079632679" xyz="0.0149 -0.0175 0"/>
      <geometry>
        <!-- <box size="${d435_cam_width} ${d435_cam_height} ${d435_cam_depth}"/> -->
        <mesh filename="package://realsense2_description/meshes/d435.dae"/>
        <!--<mesh filename="package://realsense2_description/meshes/d435/d435.dae" />-->
      </geometry>
      <material name="torso_front_camera_aluminum"/>
    </visual>
    <collision>
      <origin rpy="0 0 0" xyz="0 -0.0175 0"/>
      <geometry>
        <box size="0.02505 0.09 0.025"/>
      </geometry>
    </collision>
    <inertial>
      <!-- The following are not reliable values, and should not be used for modeling -->
      <mass value="0.564"/>
      <origin xyz="0 0 0"/>
      <inertia ixx="0.003881243" ixy="0.0" ixz="0.0" iyy="0.000498940" iyz="0.0" izz="0.003879257"/>
    </inertial>
  </link>
  <!-- camera depth joints and links -->
  <joint name="torso_front_camera_depth_joint" type="fixed">
    <origin rpy="0 0 0" xyz="0 0 0"/>
    <parent link="torso_front_camera_link"/>
    <child link="torso_front_camera_depth_frame"/>
  </joint>
  <link name="torso_front_camera_depth_frame"/>
  <joint name="torso_front_camera_depth_optical_joint" type="fixed">
    <origin rpy="-1.57079632679 0 -1.57079632679" xyz="0 0 0"/>
    <parent link="torso_front_camera_depth_frame"/>
    <child link="torso_front_camera_depth_optical_frame"/>
  </joint>
  <link name="torso_front_camera_depth_optical_frame"/>
  <!-- camera left IR joints and links -->
  <joint name="torso_front_camera_left_ir_joint" type="fixed">
    <origin rpy="0 0 0" xyz="0 0.0 0"/>
    <parent link="torso_front_camera_depth_frame"/>
    <child link="torso_front_camera_left_ir_frame"/>
  </joint>
  <link name="torso_front_camera_left_ir_frame"/>
  <joint name="torso_front_camera_left_ir_optical_joint" type="fixed">
    <origin rpy="-1.57079632679 0 -1.57079632679" xyz="0 0 0"/>
    <parent link="torso_front_camera_left_ir_frame"/>
    <child link="torso_front_camera_left_ir_optical_frame"/>
  </joint>
  <link name="torso_front_camera_left_ir_optical_frame"/>
  <!-- camera right IR joints and links -->
  <joint name="torso_front_camera_right_ir_joint" type="fixed">
    <origin rpy="0 0 0" xyz="0 -0.05 0"/>
    <parent link="torso_front_camera_depth_frame"/>
    <child link="torso_front_camera_right_ir_frame"/>
  </joint>
  <link name="torso_front_camera_right_ir_frame"/>
  <joint name="torso_front_camera_right_ir_optical_joint" type="fixed">
    <origin rpy="-1.57079632679 0 -1.57079632679" xyz="0 0 0"/>
    <parent link="torso_front_camera_right_ir_frame"/>
    <child link="torso_front_camera_right_ir_optical_frame"/>
  </joint>
  <link name="torso_front_camera_right_ir_optical_frame"/>
  <!-- camera color joints and links -->
  <joint name="torso_front_camera_color_joint" type="fixed">
    <origin rpy="0 0 0" xyz="0 0.015 0"/>
    <parent link="torso_front_camera_depth_frame"/>
    <child link="torso_front_camera_color_frame"/>
  </joint>
  <link name="torso_front_camera_color_frame"/>
  <joint name="torso_front_camera_color_optical_joint" type="fixed">
    <origin rpy="-1.57079632679 0 -1.57079632679" xyz="0 0 0"/>
    <parent link="torso_front_camera_color_frame"/>
    <child link="torso_front_camera_color_optical_frame"/>
  </joint>
  <link name="torso_front_camera_color_optical_frame"/>
  <gazebo reference="torso_front_camera_link">
    <self_collide>0</self_collide>
    <enable_wind>0</enable_wind>
    <kinematic>0</kinematic>
    <gravity>1</gravity>
    <!--<mu>1</mu>-->
    <mu2>1</mu2>
    <fdir1>0 0 0</fdir1>
    <!--<slip1>0</slip1>
      <slip2>0</slip2>-->
    <kp>1e+13</kp>
    <kd>1</kd>
    <!--<max_vel>0.01</max_vel>
      <min_depth>0</min_depth>-->
    <sensor name="torso_front_cameracolor" type="camera">
      <camera name="torso_front_camera">
        <horizontal_fov>1.21125850088</horizontal_fov>
        <image>
          <width>640</width>
          <height>480</height>
          <format>RGB_INT8</format>
        </image>
        <clip>
          <near>0.1</near>
          <far>100</far>
        </clip>
        <noise>
          <type>gaussian</type>
          <mean>0.0</mean>
          <stddev>0.007</stddev>
        </noise>
      </camera>
      <always_on>1</always_on>
      <update_rate>30</update_rate>
      <visualize>1</visualize>
    </sensor>
    <sensor name="torso_front_cameraired1" type="camera">
      <camera name="torso_front_camera">
        <horizontal_fov>1.4870205227</horizontal_fov>
        <image>
          <width>1280</width>
          <height>720</height>
          <format>L_INT8</format>
        </image>
        <clip>
          <near>0.1</near>
          <far>100</far>
        </clip>
        <noise>
          <type>gaussian</type>
          <mean>0.0</mean>
          <stddev>0.05</stddev>
        </noise>
      </camera>
      <always_on>1</always_on>
      <update_rate>90</update_rate>
      <visualize>0</visualize>
    </sensor>
    <sensor name="torso_front_cameraired2" type="camera">
      <camera name="torso_front_camera">
        <horizontal_fov>1.4870205227</horizontal_fov>
        <image>
          <width>1280</width>
          <height>720</height>
          <format>L_INT8</format>
        </image>
        <clip>
          <near>0.1</near>
          <far>100</far>
        </clip>
        <noise>
          <type>gaussian</type>
          <mean>0.0</mean>
          <stddev>0.05</stddev>
        </noise>
      </camera>
      <always_on>1</always_on>
      <update_rate>90</update_rate>
      <visualize>0</visualize>
    </sensor>
    <sensor name="torso_front_cameradepth" type="depth">
      <camera name="torso_front_camera">
        <horizontal_fov>1.4870205227</horizontal_fov>
        <image>
          <width>1280</width>
          <height>720</height>
        </image>
        <clip>
          <near>0.1</near>
          <far>100</far>
        </clip>
        <noise>
          <type>gaussian</type>
          <mean>0.0</mean>
          <stddev>0.100</stddev>
        </noise>
      </camera>
      <always_on>1</always_on>
      <update_rate>90</update_rate>
      <visualize>0</visualize>
    </sensor>
  </gazebo>
  <gazebo>
    <plugin filename="librealsense_gazebo_plugin.so" name="torso_front_camera">
      <prefix>torso_front_camera</prefix>
      <depthUpdateRate>30.0</depthUpdateRate>
      <colorUpdateRate>30.0</colorUpdateRate>
      <infraredUpdateRate>30.0</infraredUpdateRate>
      <depthTopicName>depth/image_raw</depthTopicName>
      <depthCameraInfoTopicName>depth/camera_info</depthCameraInfoTopicName>
      <colorTopicName>color/image_raw</colorTopicName>
      <colorCameraInfoTopicName>color/camera_info</colorCameraInfoTopicName>
      <infrared1TopicName>infra1/image_raw</infrared1TopicName>
      <infrared1CameraInfoTopicName>infra1/camera_info</infrared1CameraInfoTopicName>
      <infrared2TopicName>infra2/image_raw</infrared2TopicName>
      <infrared2CameraInfoTopicName>infra2/camera_info</infrared2CameraInfoTopicName>
      <colorOpticalframeName>torso_front_camera_color_optical_frame</colorOpticalframeName>
      <depthOpticalframeName>torso_front_camera_depth_optical_frame</depthOpticalframeName>
      <infrared1OpticalframeName>torso_front_camera_left_ir_optical_frame</infrared1OpticalframeName>
      <infrared2OpticalframeName>torso_front_camera_right_ir_optical_frame</infrared2OpticalframeName>
      <rangeMinDepth>0.2</rangeMinDepth>
      <rangeMaxDepth>10.0</rangeMaxDepth>
      <pointCloud>True</pointCloud>
      <pointCloudTopicName>depth/color/points</pointCloudTopicName>
      <pointCloudCutoff>0.25</pointCloudCutoff>
      <pointCloudCutoffMax>9.0</pointCloudCutoffMax>
    </plugin>
  </gazebo>
  <material name="torso_back_camera_aluminum">
    <color rgba="0.5 0.5 0.5 1"/>
  </material>
  <!-- camera body, with origin at camera_link -->
  <joint name="torso_back_camera_pose_frame_joint" type="fixed">
    <origin rpy="0.0 0.261799387799 3.14159265359" xyz="-0.3275 0.009 1.0337"/>
    <parent link="base_link"/>
    <child link="torso_back_camera_pose_frame"/>
  </joint>
  <link name="torso_back_camera_pose_frame"/>
  <joint name="torso_back_camera_pose_joint" type="fixed">
    <origin rpy="1.57079632679 0 -1.57079632679" xyz="0 0 0"/>
    <parent link="torso_back_camera_pose_frame"/>
    <child link="torso_back_camera_link"/>
  </joint>
  <link name="torso_back_camera_link">
    <visual>
      <origin rpy="0 0 0" xyz="0 0 0"/>
      <geometry>
        <mesh filename="package://realsense2_description/meshes/t265.stl"/>
      </geometry>
      <material name="torso_back_camera_aluminum"/>
    </visual>
    <collision>
      <origin rpy="0 0 0" xyz="0 0 0"/>
      <geometry>
        <mesh filename="package://realsense2_description/meshes/t265.stl"/>
      </geometry>
    </collision>
    <inertial>
      <!-- The following are not reliable values, and should not be used for modeling -->
      <mass value="0.068024"/>
      <origin xyz="0 0 0"/>
      <inertia ixx="0.0000039782" ixy="0.0" ixz="0.000000034641" iyy="0.000065045" iyz="0.0" izz="0.000067499"/>
    </inertial>
  </link>
  <joint name="torso_back_camera_fisheye1_rgb_joint" type="fixed">
    <origin rpy="0 1.57079632679 1.57079632679" xyz="-0.0411 0.0 0.0"/>
    <parent link="torso_back_camera_link"/>
    <child link="torso_back_camera_fisheye1_rgb_frame"/>
  </joint>
  <link name="torso_back_camera_fisheye1_rgb_frame"/>
  <joint name="torso_back_camera_fisheye2_rgb_joint" type="fixed">
    <origin rpy="0 1.57079632679 1.57079632679" xyz="0.0229 0.0 0.0"/>
    <parent link="torso_back_camera_link"/>
    <child link="torso_back_camera_fisheye2_rgb_frame"/>
  </joint>
  <link name="torso_back_camera_fisheye2_rgb_frame"/>
  <joint name="torso_back_camera_fisheye1_optical_joint" type="fixed">
    <origin rpy="-1.57079632679 0 -1.57079632679" xyz="0 0 0"/>
    <parent link="torso_back_camera_fisheye1_rgb_frame"/>
    <child link="torso_back_camera_fisheye1_optical_frame"/>
  </joint>
  <link name="torso_back_camera_fisheye1_optical_frame"/>
  <joint name="torso_back_camera_fisheye2_optical_joint" type="fixed">
    <origin rpy="-1.57079632679 0 -1.57079632679" xyz="0 0 0"/>
    <parent link="torso_back_camera_fisheye2_rgb_frame"/>
    <child link="torso_back_camera_fisheye2_optical_frame"/>
  </joint>
  <link name="torso_back_camera_fisheye2_optical_frame"/>
  <!-- camera depth joints and links -->
  <joint name="torso_back_camera_gyro_optical_joint" type="fixed">
    <origin rpy="0 3.14159265359 0" xyz="-0.0311 0 0.00655"/>
    <parent link="torso_back_camera_link"/>
    <child link="torso_back_camera_gyro_optical_frame"/>
  </joint>
  <link name="torso_back_camera_gyro_optical_frame"/>
  <joint name="torso_back_camera_accel_optical_joint" type="fixed">
    <origin rpy="0 0 0" xyz="0 0 0"/>
    <parent link="torso_back_camera_gyro_optical_frame"/>
    <child link="torso_back_camera_accel_optical_frame"/>
  </joint>
  <link name="torso_back_camera_accel_optical_frame"/>
  <!-- Load parameters to model's main link-->
  <gazebo reference="torso_back_camera_fisheye1_rgb_frame">
    <self_collide>0</self_collide>
    <enable_wind>0</enable_wind>
    <kinematic>0</kinematic>
    <gravity>1</gravity>
    <!--<mu>1</mu>-->
    <mu2>1</mu2>
    <fdir1>0 0 0</fdir1>
    <!--<slip1>0</slip1>
      <slip2>0</slip2>-->
    <kp>1e+13</kp>
    <kd>1</kd>
    <!--<max_vel>0.01</max_vel>
      <min_depth>0</min_depth>-->
    <sensor name="torso_back_camerafisheye1" type="wideanglecamera">
      <origin rpy="0 1.57079632679 0" xyz="0 0 0"/>
      <update_rate>30</update_rate>
      <camera>
        <horizontal_fov>1.95</horizontal_fov>
        <image>
          <width>848</width>
          <height>800</height>
        </image>
        <clip>
          <near>0.2</near>
          <far>100</far>
        </clip>
        <lens>
          <!-- type element is mandatory -->
          <type>orthographic</type>
          <!-- if it is set to `true` your horizontal FOV will remain as defined -->
          <!-- othervise it depends on lens type and custom function, if there is one -->
          <scale_to_hfov>true</scale_to_hfov>
          <!-- clip everything that is outside of this angle -->
          <!-- eye balled value for these cameras-->
          <cutoff_angle>2.20</cutoff_angle>
          <!-- resolution of the cubemap texture, the highter it is - the sharper is your image -->
          <env_texture_size>1024</env_texture_size>
        </lens>
        <!--<distortion>-->
        <!--<k1>-0.00040996368625201285</k1>-->
        <!--<k2>0.03653175011277199</k2>-->
        <!--<k3>0.0</k3>-->
        <!--<p1>-0.034823670983314514</p1>-->
        <!--<p2>0.0052825710736215115</p2>-->
        <!--<center>0.5 0.5</center>-->
        <!--</distortion>-->
      </camera>
      <plugin filename="libgazebo_ros_camera.so" name="torso_back_camerafisheye1">
        <alwaysOn>true</alwaysOn>
        <updateRate>30.0</updateRate>
        <cameraName>torso_back_camera/fisheye1</cameraName>
        <imageTopicName>image_raw</imageTopicName>
        <cameraInfoTopicName>camera_info</cameraInfoTopicName>
        <frameName>torso_back_camera_fisheye1_optical_frame</frameName>
        <hackBaseline>0.07</hackBaseline>
        <distortionK1>-0.00040996368625201285</distortionK1>
        <distortionK2>0.03653175011277199</distortionK2>
        <distortionK3>0.0</distortionK3>
        <distortionP1>-0.034823670983314514</distortionP1>
        <distortionP2>0.0052825710736215115</distortionP2>
        <Cx>416.22</Cx>
        <Cy>402.1</Cy>
        <CxPrime>416.22</CxPrime>
      </plugin>
    </sensor>
  </gazebo>
  <gazebo reference="torso_back_camera_fisheye2_rgb_frame">
    <self_collide>0</self_collide>
    <enable_wind>0</enable_wind>
    <kinematic>0</kinematic>
    <gravity>1</gravity>
    <!--<mu>1</mu>-->
    <mu2>1</mu2>
    <fdir1>0 0 0</fdir1>
    <!--<slip1>0</slip1>
      <slip2>0</slip2>-->
    <kp>1e+13</kp>
    <kd>1</kd>
    <!--<max_vel>0.01</max_vel>
      <min_depth>0</min_depth>-->
    <sensor name="torso_back_camerafisheye2" type="wideanglecamera">
      <origin rpy="0 1.57079632679 0" xyz="0 0 0"/>
      <update_rate>30</update_rate>
      <camera>
        <horizontal_fov>2.84</horizontal_fov>
        <image>
          <width>848</width>
          <height>800</height>
        </image>
        <clip>
          <near>0.1</near>
          <far>100</far>
        </clip>
        <lens>
          <!-- type element is mandatory -->
          <type>orthographic</type>
          <!-- if it is set to `true` your horizontal FOV will remain as defined -->
          <!-- othervise it depends on lens type and custom function, if there is one -->
          <scale_to_hfov>true</scale_to_hfov>
          <!-- clip everything that is outside of this angle -->
          <!-- eye balled value for these cameras-->
          <cutoff_angle>2.20</cutoff_angle>
          <!-- resolution of the cubemap texture, the highter it is - the sharper is your image -->
          <env_texture_size>1024</env_texture_size>
        </lens>
        <!--<distortion>-->
        <!--<k1>-0.00040996368625201285</k1>-->
        <!--<k2>0.03653175011277199</k2>-->
        <!--<k3>0.0</k3>-->
        <!--<p1>-0.034823670983314514</p1>-->
        <!--<p2>0.0052825710736215115</p2>-->
        <!--<center>0.5 0.5</center>-->
        <!--</distortion>-->
      </camera>
      <always_on>1</always_on>
      <plugin filename="libgazebo_ros_camera.so" name="torso_back_camerafisheye2">
        <alwaysOn>true</alwaysOn>
        <updateRate>30.0</updateRate>
        <cameraName>torso_back_camera/fisheye2</cameraName>
        <imageTopicName>image_raw</imageTopicName>
        <cameraInfoTopicName>camera_info</cameraInfoTopicName>
        <frameName>torso_back_camera_fisheye2_optical_frame</frameName>
        <hackBaseline>0.07</hackBaseline>
        <distortionK1>-0.00040996368625201285</distortionK1>
        <distortionK2>0.03653175011277199</distortionK2>
        <distortionK3>0.0</distortionK3>
        <distortionP1>-0.034823670983314514</distortionP1>
        <distortionP2>0.0052825710736215115</distortionP2>
      </plugin>
    </sensor>
  </gazebo>
  <link name="torso_mic_front_link"/>
  <joint name="torso_mic_front_joint" type="fixed">
    <origin rpy="1.3962634016 0 1.57079632679" xyz="-0.12173 -3.5497E-05 0.80332"/>
    <child link="torso_mic_front_link"/>
    <parent link="base_link"/>
  </joint>
  <link name="head_1_link">
    <inertial>
      <origin rpy="0 0 0" xyz="0.011917 0.00089501 0.08"/>
      <mass value="0.35824"/>
      <inertia ixx="0.00038949" ixy="-2.99E-07" ixz="-1.0058E-05" iyy="0.0002826" iyz="-1.3354E-09" izz="0.00038119"/>
    </inertial>
    <visual>
      <origin rpy="0 0 0" xyz="0 0 0"/>
      <geometry>
        <mesh filename="package://ari_description/meshes/head/head_1.stl" scale="1 1 1"/>
      </geometry>
      <material name="White"/>
    </visual>
    <collision>
      <origin rpy="0 0 0.0" xyz="0.0 0 0"/>
      <geometry>
        <mesh filename="package://ari_description/meshes/head/head_1_collision.stl" scale="1 1 1"/>
      </geometry>
      <material name="White"/>
    </collision>
  </link>
  <joint name="head_1_joint" type="revolute">
    <parent link="base_link"/>
    <child link="head_1_link"/>
    <origin rpy="0 0 0" xyz="-0.2255 0 1.1915"/>
    <axis xyz="0 0 1"/>
    <limit effort="3.4" lower="-1.308996939" upper="1.308996939" velocity="3.0"/>
    <dynamics damping="0.5" friction="1.0"/>
    <safety_controller k_position="20" k_velocity="20" soft_lower_limit="-1.238996939" soft_upper_limit="1.238996939"/>
  </joint>
  <gazebo reference="head_1_link">
    <mu1>0.9</mu1>
    <mu2>0.9</mu2>
    <material>Gazebo/White</material>
  </gazebo>
  <gazebo reference="head_1_joint">
    <implicitSpringDamper>1</implicitSpringDamper>
  </gazebo>
  <transmission name="head_1_trans">
    <type>transmission_interface/SimpleTransmission</type>
    <actuator name="head_1_motor">
      <mechanicalReduction>1</mechanicalReduction>
    </actuator>
    <joint name="head_1_joint">
      <offset>0.0</offset>
      <hardwareInterface>hardware_interface/JointStateInterface</hardwareInterface>
      <hardwareInterface>hardware_interface/PositionJointInterface</hardwareInterface>
    </joint>
  </transmission>
  <link name="head_2_link">
    <inertial>
      <origin rpy="0 0 0" xyz="-0.00696564558843529 0.101996367574138 -0.0008447177604265"/>
      <mass value="0.87177"/>
      <inertia ixx="0.00348124070979026" ixy="-0.000574703524917147" ixz="3.53158443864736E-08" iyy="0.0023941695403699" iyz="2.1916879659837E-07" izz="0.00298511989538667"/>
    </inertial>
    <visual>
      <origin rpy="0 0 0" xyz="0 0 0"/>
      <geometry>
        <mesh filename="package://ari_description/meshes/head/head_2.stl" scale="1 1 1"/>
      </geometry>
      <material name="White"/>
    </visual>
    <collision>
      <origin rpy="0 0 0" xyz="0 0 0"/>
      <geometry>
        <mesh filename="package://ari_description/meshes/head/head_2_collision.stl" scale="1 1 1"/>
      </geometry>
      <material name="White"/>
    </collision>
  </link>
  <joint name="head_2_joint" type="revolute">
    <parent link="head_1_link"/>
    <child link="head_2_link"/>
    <origin rpy="1.57079632679 0 0" xyz="0.0425000000000001 0 0.093"/>
    <axis xyz="0 0 -1"/>
    <limit effort="3.26" lower="-0.261799387799" upper="0.436332312999" velocity="3.0"/>
    <dynamics damping="0.5" friction="1.0"/>
    <safety_controller k_position="20" k_velocity="20" soft_lower_limit="-0.191799387799" soft_upper_limit="0.366332312999"/>
  </joint>
  <gazebo reference="head_2_link">
    <material>Gazebo/White</material>
  </gazebo>
  <transmission name="head_2_trans">
    <type>transmission_interface/SimpleTransmission</type>
    <actuator name="head_2_motor">
      <mechanicalReduction>1</mechanicalReduction>
    </actuator>
    <joint name="head_2_joint">
      <offset>0.0</offset>
      <hardwareInterface>hardware_interface/JointStateInterface</hardwareInterface>
      <hardwareInterface>hardware_interface/PositionJointInterface</hardwareInterface>
    </joint>
  </transmission>
  <link name="head_front_camera_link">
    <inertial>
      <origin rpy="0 0 0" xyz="-0.00619317919404934 -4.45435622691566E-05 -8.22112600169511E-05"/>
      <mass value="0.00115745344894968"/>
      <inertia ixx="6.76913771029748E-08" ixy="2.52492243040059E-13" ixz="-3.60412180500293E-11" iyy="2.88827920072855E-08" iyz="-1.65336506314803E-13" izz="3.97290092554434E-08"/>
    </inertial>
    <visual>
      <origin rpy="0 0 0" xyz="0 0 0"/>
      <geometry>
        <mesh filename="package://ari_description/meshes/sensors/head_front_camera.stl" scale="1 1 1"/>
      </geometry>
      <material name="DarkGrey"/>
    </visual>
    <collision>
      <origin rpy="0 0 0" xyz="0 0 0"/>
      <geometry>
        <mesh filename="package://ari_description/meshes/sensors/head_front_camera.stl" scale="1 1 1"/>
      </geometry>
    </collision>
  </link>
  <joint name="head_front_camera_joint" type="fixed">
    <origin rpy="-1.57079632679 0 0" xyz="0.0633629998680001 0.181996035631448 0"/>
    <parent link="head_2_link"/>
    <child link="head_front_camera_link"/>
    <axis xyz="0 0 0"/>
  </joint>
  <joint name="head_front_camera_optical_joint" type="fixed">
    <origin rpy="-1.57079632679 0 -1.57079632679" xyz="0.0 0.0 0.0"/>
    <parent link="head_front_camera_link"/>
    <child link="head_front_camera_optical_frame"/>
    <axis xyz="0 0 0"/>
  </joint>
  <link name="head_front_camera_optical_frame"/>
  <joint name="ear_led_left_link" type="fixed">
    <origin rpy="-0.1 0 0.0" xyz="0.021 0.095 0.192"/>
    <child link="ear_led_left_frame"/>
    <parent link="head_1_link"/>
  </joint>
  <link name="ear_led_left_frame">
    <inertial>
      <origin rpy="0 0 0" xyz="0 0 0"/>
      <mass value="0.001"/>
      <!-- matrix below must not be zero, or Gazebo won't load -->
      <inertia ixx="0.0001" ixy="0.0" ixz="0.0" iyy="0.000001" iyz="0.0" izz="0.0001"/>
    </inertial>
  </link>
  <joint name="ear_led_right_link" type="fixed">
    <origin rpy="-0.1 0.0 3.14" xyz="0.021 -0.095 0.192"/>
    <child link="ear_led_right_frame"/>
    <parent link="head_1_link"/>
  </joint>
  <link name="ear_led_right_frame">
    <inertial>
      <origin rpy="0 0 0" xyz="0 0 0"/>
      <mass value="0.001"/>
      <!-- matrix below must not be zero, or Gazebo won't load -->
      <inertia ixx="0.0001" ixy="0.0" ixz="0.0" iyy="0.000001" iyz="0.0" izz="0.0001"/>
    </inertial>
  </link>
  <gazebo reference="head_front_camera_link">
    <sensor name="head_front_camera_pi_camera" type="camera">
      <update_rate>30.0</update_rate>
      <camera name="head_front_camera_camera">
        <horizontal_fov>1.3962634016</horizontal_fov>
        <image>
          <width>1280</width>
          <height>960</height>
          <format>B8G8R8</format>
        </image>
        <clip>
          <near>0.02</near>
          <far>300</far>
        </clip>
        <noise>
          <type>gaussian</type>
          <!-- Noise is sampled independently per pixel on each frame.
                 That pixel's noise value is added to each of its color
                 channels, which at that point lie in the range [0,1]. -->
          <mean>0.0</mean>
          <stddev>0.007</stddev>
        </noise>
      </camera>
      <plugin filename="libgazebo_ros_camera.so" name="head_front_camera_camera_controller">
        <alwaysOn>true</alwaysOn>
        <updateRate>30.0</updateRate>
        <cameraName>head_front_camera</cameraName>
        <imageTopicName>image_raw</imageTopicName>
        <cameraInfoTopicName>camera_info</cameraInfoTopicName>
        <frameName>head_front_camera_optical_frame</frameName>
        <hackBaseline>0.07</hackBaseline>
        <distortionK1>0.00000001</distortionK1>
        <distortionK2>0.00000001</distortionK2>
        <distortionK3>0.00000001</distortionK3>
        <distortionT1>0.00000001</distortionT1>
        <distortionT2>0.00000001</distortionT2>
      </plugin>
    </sensor>
  </gazebo>
  <!--************************-->
  <!--      ARM_BASE_LINK     -->
  <!--************************-->
  <link name="arm_left_base_link">
    <inertial>
      <origin rpy="0 0 0" xyz="0.010252 -2.0895E-06 -0.010085"/>
      <mass value="0.41717"/>
      <inertia ixx="0.00020772" ixy="6.9296E-09" ixz="3.5124E-08" iyy="0.00033949" iyz="-5.2354E-09" izz="0.00046362"/>
    </inertial>
    <visual>
      <origin rpy="0 0 0" xyz="0 0 0"/>
      <geometry>
        <mesh filename="package://ari_description/meshes/arm/arm_base.stl" scale="1 1 1"/>
      </geometry>
      <material name="Grey">
        <color rgba="0.29804 0.29804 0.29804 1"/>
      </material>
    </visual>
    <collision>
      <origin rpy="0 0 0" xyz="0 0 0"/>
      <geometry>
        <mesh filename="package://ari_description/meshes/arm/arm_base_collision.stl" scale="1 1 1"/>
      </geometry>
    </collision>
  </link>
  <joint name="arm_left_base_joint" type="fixed">
    <origin rpy="1.83259571459 0.0 -3.14159265359" xyz="-0.219 0.097624 1.1111"/>
    <child link="arm_left_base_link"/>
    <parent link="base_link"/>
  </joint>
  <!--************************-->
  <!--        SHOULDER        -->
  <!--************************-->
  <link name="arm_left_1_link">
    <inertial>
      <!--       <origin xyz="-0.012604 ${-0.00045914 * reflect} 0.082789" rpy="0.0 0.0 0.0"/> -->
      <origin rpy="0.0 0.0 0.0" xyz="-0.012773 -0.00044 0.083205"/>
      <mass value="0.730376620707115"/>
      <inertia ixx="0.000883728615044291" ixy="3.94329374494e-06" ixz="9.80047375813158E-05" iyy="0.000710081638353236" iyz="-3.01812335433e-06" izz="0.000572003714116628"/>
    </inertial>
    <visual>
      <origin rpy="0 0 0" xyz="0 0 0"/>
      <geometry>
        <mesh filename="package://ari_description/meshes/arm/arm_1.stl" scale="1 1 1"/>
      </geometry>
      <material name="White"/>
    </visual>
    <collision>
      <origin rpy="0 0 0" xyz="0 0 0"/>
      <geometry>
        <mesh filename="package://ari_description/meshes/arm/arm_1_collision.stl" scale="1 1 1"/>
      </geometry>
    </collision>
  </link>
  <joint name="arm_left_1_joint" type="revolute">
    <parent link="arm_left_base_link"/>
    <child link="arm_left_1_link"/>
    <origin rpy="0.0 0.0 0.0" xyz="0.0 0.0 0.0"/>
    <axis xyz="0 0 -1"/>
    <limit effort="10.0" lower="-2.09439510239" upper="2.09439510239" velocity="1.95"/>
    <dynamics damping="1.0" friction="1.0"/>
    <safety_controller k_position="20" k_velocity="20" soft_lower_limit="-2.02439510239" soft_upper_limit="2.02439510239"/>
  </joint>
  <link name="arm_left_2_link">
    <inertial>
      <origin rpy="0.0 0.0 0.0" xyz="0.0037554 0.0474088 0.01356828"/>
      <mass value="0.5891913"/>
      <inertia ixx="0.0006238" ixy="-6.0701879e-06" ixz="9.3542493E-06" iyy="0.0005140" iyz="9.8910641e-05" izz="0.0007757"/>
    </inertial>
    <visual>
      <origin rpy="0 0 0" xyz="0 0 0"/>
      <geometry>
        <mesh filename="package://ari_description/meshes/arm/arm_2.stl" scale="1 1 1"/>
      </geometry>
      <material name="White"/>
    </visual>
    <collision>
      <origin rpy="0 0 0" xyz="0 0 0"/>
      <geometry>
        <mesh filename="package://ari_description/meshes/arm/arm_2_collision.stl" scale="1 1 1"/>
      </geometry>
    </collision>
  </link>
  <joint name="arm_left_2_joint" type="revolute">
    <parent link="arm_left_1_link"/>
    <child link="arm_left_2_link"/>
    <origin rpy="1.5708 -1.309 1.5708" xyz="-0.001 0 0.1145"/>
    <axis xyz="0 0 -1"/>
    <limit effort="10.0" lower="-0.0872664625997" upper="2.70526034059" velocity="1.95"/>
    <dynamics damping="1.0" friction="1.0"/>
    <safety_controller k_position="20" k_velocity="20" soft_lower_limit="-0.0172664625997" soft_upper_limit="2.63526034059"/>
  </joint>
  <link name="arm_left_3_link">
    <inertial>
      <origin rpy="0.0 0.0 0.0" xyz="-0.0054056 -0.0083079 0.06942"/>
      <mass value="0.4650332"/>
      <inertia ixx="0.0004078" ixy="5.2043217e-05" ixz="3.12599823E-05" iyy="0.0004135" iyz="2.6803484e-05" izz="0.0003238"/>
    </inertial>
    <visual>
      <origin rpy="0 0 0" xyz="0 0 0"/>
      <geometry>
        <mesh filename="package://ari_description/meshes/arm/arm_3.stl" scale="1 1 1"/>
      </geometry>
      <material name="White"/>
    </visual>
    <collision>
      <origin rpy="0 0 0" xyz="0 0 0"/>
      <geometry>
        <mesh filename="package://ari_description/meshes/arm/arm_3_collision.stl" scale="1 1 1"/>
      </geometry>
    </collision>
  </link>
  <joint name="arm_left_3_joint" type="revolute">
    <parent link="arm_left_2_link"/>
    <child link="arm_left_3_link"/>
    <origin rpy="-1.57079632679 -0.785398163397 0.0" xyz="0.005 0.10157 0.001"/>
    <axis xyz="0 0 -1"/>
    <limit effort="5" lower="-2.09439510239" upper="2.09439510239" velocity="2.35"/>
    <dynamics damping="1.0" friction="1.0"/>
    <safety_controller k_position="20" k_velocity="20" soft_lower_limit="-2.02439510239" soft_upper_limit="2.02439510239"/>
  </joint>
  <!--************************-->
  <!--        ELBOW           -->
  <!--************************-->
  <link name="arm_left_4_link">
    <inertial>
      <origin rpy="0.0 0.0 0.0" xyz="0.0005502 -0.1185841 0.0184109"/>
      <mass value="0.5958179"/>
      <inertia ixx="0.00406585545706706" ixy="-0.000203216283995562" ixz="-8.35772941748004E-06" iyy="0.000334720111921714" iyz="-0.00015724504214636" izz="0.00422931703883722"/>
    </inertial>
    <visual>
      <origin rpy="0 0 0" xyz="0 0 0"/>
      <geometry>
        <mesh filename="package://ari_description/meshes/arm/arm_4.stl" scale="1 1 1"/>
      </geometry>
      <material name="White"/>
    </visual>
    <collision>
      <origin rpy="0 0 0" xyz="0 0 0"/>
      <origin rpy="0 0 0" xyz="0 0 0"/>
      <geometry>
        <mesh filename="package://ari_description/meshes/arm/arm_4_collision.stl" scale="1 1 1"/>
      </geometry>
    </collision>
  </link>
  <joint name="arm_left_4_joint" type="revolute">
    <parent link="arm_left_3_link"/>
    <child link="arm_left_4_link"/>
    <origin rpy="-1.57079632679 0.0 -0.785398163397" xyz="-0.0042426 -0.0042426 0.1001"/>
    <axis xyz="0 0 -1"/>
    <limit effort="5" lower="-0.0872664625997" upper="2.35619449019" velocity="2.35"/>
    <dynamics damping="1.0" friction="1.0"/>
    <safety_controller k_position="20" k_velocity="20" soft_lower_limit="-0.0172664625997" soft_upper_limit="2.28619449019"/>
  </joint>
  <!-- Tool Link -->
  <link name="arm_left_tool_link">
    <inertial>
      <origin rpy="0 0 0" xyz="0 0 0"/>
      <mass value="0.0001"/>
      <inertia ixx="0.00001" ixy="0.0" ixz="0.0" iyy="0.00001" iyz="0.0" izz="0.00001"/>
    </inertial>
  </link>
  <joint name="arm_left_tool_joint" type="fixed">
    <origin rpy="-1.5708 -0.2618 1.5708" xyz="0 -0.35231 0.0011086"/>
    <parent link="arm_left_4_link"/>
    <child link="arm_left_tool_link"/>
    <axis xyz="0 0 0"/>
  </joint>
  <joint name="hand_left_fingers_joint" type="revolute">
    <parent link="arm_left_tool_link"/>
    <child link="hand_left_fingers_link"/>
    <origin rpy="3.1416 0.0 0.0" xyz="0 0 0.0"/>
    <axis xyz="0 0 1"/>
    <limit effort="4.0" lower="0.0" upper="1.308996939" velocity="2.5"/>
    <dynamics damping="0.5" friction="0.0"/>
    <!-- TODO: Tune -->
    <safety_controller k_position="20" k_velocity="20" soft_lower_limit="0.0" soft_upper_limit="1.308996939"/>
  </joint>
  <link name="hand_left_fingers_link">
    <inertial>
      <origin rpy="0 0 0" xyz="0 0 0"/>
      <mass value="0.05"/>
      <inertia ixx="0.001" ixy="0" ixz="0" iyy="0.001" iyz="0" izz="0.001"/>
      <!--To stabilize simulation-->
    </inertial>
    <visual>
      <origin rpy="0 0 0" xyz="0 0 0"/>
      <geometry>
        <sphere radius="0.001"/>
      </geometry>
      <material name="White"/>
    </visual>
    <collision>
      <origin rpy="0 0 0" xyz="0 0 0"/>
      <geometry>
        <sphere radius="0.001"/>
      </geometry>
    </collision>
  </link>
  <transmission name="hand_left_fingers_trans">
    <type>transmission_interface/SimpleTransmission</type>
    <actuator name="hand_left_fingers_motor">
      <mechanicalReduction>1.0</mechanicalReduction>
    </actuator>
    <joint name="hand_left_fingers_joint">
      <hardwareInterface>hardware_interface/PositionJointInterface</hardwareInterface>
    </joint>
  </transmission>
  <link name="arm_left_grasping_frame"/>
  <joint name="arm_left_grasping_fixed_joint" type="fixed">
    <parent link="arm_left_4_link"/>
    <child link="arm_left_grasping_frame"/>
    <axis xyz="0 0 1"/>
    <origin rpy="-1.5708 -0.2618 1.5708" xyz="0 -0.35231 0.0011086"/>
  </joint>
  <link name="hand_left_1_link">
    <inertial>
      <origin rpy="0 0 0" xyz="-0.0194858087119051 -0.00284946290069976 -0.000289044791174375"/>
      <mass value="0.0400715645648009"/>
      <inertia ixx="1.56769636746935E-06" ixy="2.22831013516217E-08" ixz="7.74537720537552E-09" iyy="4.6054803967178E-06" iyz="2.08251121489226E-10" izz="4.01623373583446E-06"/>
    </inertial>
    <visual>
      <origin rpy="0 0 0" xyz="0 0 0"/>
      <geometry>
        <mesh filename="package://ari_description/meshes/arm/hand_1.stl" scale="1 1 1"/>
      </geometry>
      <material name="">
        <color rgba="0.752941176470588 0.752941176470588 0.752941176470588 1"/>
      </material>
    </visual>
    <collision>
      <origin rpy="0 0 0" xyz="0 0 0"/>
      <geometry>
        <mesh filename="package://ari_description/meshes/arm/hand_1_collision.stl" scale="1 1 1"/>
      </geometry>
    </collision>
  </link>
  <joint name="hand_left_virtual_1_joint" type="revolute">
    <origin rpy="-1.5708 -0.2618 1.5708" xyz="0 -0.35231 0.0011086"/>
    <parent link="arm_left_4_link"/>
    <child link="hand_left_1_link"/>
    <axis xyz="0 0 -1"/>
    <limit effort="1.0" lower="0" upper="1.35" velocity="2.0"/>
    <!--
      <dynamics friction="${arm_friction}" damping="${arm_damping}"/>
      <safety_controller k_position="20"
                           k_velocity="20"
                           soft_lower_limit="${0.0 + arm_eps}"
                           soft_upper_limit="${1.5708 - arm_eps}" />
  -->
  </joint>
  <link name="hand_left_2_link">
    <inertial>
      <origin rpy="0 0 0" xyz="-0.0159508701186225 0.00214676466101674 0.000361575914240066"/>
      <mass value="0.0262043707272721"/>
      <inertia ixx="9.15137557050205E-07" ixy="5.3927377524493E-07" ixz="-5.3325168061876E-09" iyy="2.67374552400975E-06" iyz="-6.4411286354103E-10" izz="2.38630247657937E-06"/>
    </inertial>
    <visual>
      <origin rpy="0 0 0" xyz="0 0 0"/>
      <geometry>
        <mesh filename="package://ari_description/meshes/arm/hand_2.stl" scale="1 1 1"/>
      </geometry>
      <material name="">
        <color rgba="0.752941176470588 0.752941176470588 0.752941176470588 1"/>
      </material>
    </visual>
    <collision>
      <origin rpy="0 0 0" xyz="0 0 0"/>
      <geometry>
        <mesh filename="package://ari_description/meshes/arm/hand_2_collision.stl" scale="1 1 1"/>
      </geometry>
    </collision>
  </link>
  <joint name="hand_left_virtual_2_joint" type="revolute">
    <origin rpy="0 0 0" xyz="-0.037185 0.0001459 0"/>
    <parent link="hand_left_1_link"/>
    <child link="hand_left_2_link"/>
    <axis xyz="0 0 -1"/>
    <limit effort="1.0" lower="0" upper="1.5708" velocity="2.0"/>
    <!--
      <dynamics friction="${arm_friction}" damping="${arm_damping}"/>
      <safety_controller k_position="20"
                           k_velocity="20"
                           soft_lower_limit="${0.0 + arm_eps}"
                           soft_upper_limit="${1.5708 - arm_eps}" />
  -->
  </joint>
  <gazebo reference="arm_left_1_link">
    <mu1>0.9</mu1>
    <mu2>0.9</mu2>
    <material>Gazebo/DarkGrey</material>
  </gazebo>
  <gazebo reference="arm_left_2_link">
    <mu1>0.9</mu1>
    <mu2>0.9</mu2>
    <material>Gazebo/DarkGrey</material>
  </gazebo>
  <gazebo reference="arm_left_3_link">
    <mu1>0.9</mu1>
    <mu2>0.9</mu2>
    <material>Gazebo/DarkGrey</material>
  </gazebo>
  <gazebo reference="arm_left_4_link">
    <mu1>0.9</mu1>
    <mu2>0.9</mu2>
    <material>Gazebo/DarkGrey</material>
  </gazebo>
  <gazebo reference="hand_left_1_link">
    <mu1>0.9</mu1>
    <mu2>0.9</mu2>
    <material>Gazebo/DarkGrey</material>
  </gazebo>
  <gazebo reference="hand_left_2_link">
    <mu1>0.9</mu1>
    <mu2>0.9</mu2>
    <material>Gazebo/DarkGrey</material>
  </gazebo>
  <gazebo reference="arm_left_1_joint">
    <implicitSpringDamper>1</implicitSpringDamper>
  </gazebo>
  <gazebo reference="arm_left_2_joint">
    <implicitSpringDamper>1</implicitSpringDamper>
  </gazebo>
  <gazebo reference="arm_left_3_joint">
    <implicitSpringDamper>1</implicitSpringDamper>
  </gazebo>
  <gazebo reference="arm_left_4_joint">
    <implicitSpringDamper>1</implicitSpringDamper>
  </gazebo>
  <gazebo reference="hand_left_virtual_1_joint">
    <implicitSpringDamper>1</implicitSpringDamper>
  </gazebo>
  <gazebo reference="hand_left_virtual_2_joint">
    <implicitSpringDamper>1</implicitSpringDamper>
  </gazebo>
  <transmission name="arm_left_1_trans">
    <type>transmission_interface/SimpleTransmission</type>
    <actuator name="arm_left_1_motor">
      <mechanicalReduction>1.0</mechanicalReduction>
    </actuator>
    <joint name="arm_left_1_joint">
      <offset>0.0</offset>
      <hardwareInterface>hardware_interface/PositionJointInterface</hardwareInterface>
      <hardwareInterface>hardware_interface/EffortJointInterface</hardwareInterface>
      <hardwareInterface>hardware_interface/JointStateInterface</hardwareInterface>
    </joint>
  </transmission>
  <transmission name="arm_left_2_trans">
    <type>transmission_interface/SimpleTransmission</type>
    <actuator name="arm_left_2_motor">
      <mechanicalReduction>1.0</mechanicalReduction>
    </actuator>
    <joint name="arm_left_2_joint">
      <offset>0.0</offset>
      <hardwareInterface>hardware_interface/PositionJointInterface</hardwareInterface>
      <hardwareInterface>hardware_interface/EffortJointInterface</hardwareInterface>
      <hardwareInterface>hardware_interface/JointStateInterface</hardwareInterface>
    </joint>
  </transmission>
  <transmission name="arm_left_3_trans">
    <type>transmission_interface/SimpleTransmission</type>
    <actuator name="arm_left_3_motor">
      <mechanicalReduction>1.0</mechanicalReduction>
    </actuator>
    <joint name="arm_left_3_joint">
      <offset>0.0</offset>
      <hardwareInterface>hardware_interface/PositionJointInterface</hardwareInterface>
      <hardwareInterface>hardware_interface/EffortJointInterface</hardwareInterface>
      <hardwareInterface>hardware_interface/JointStateInterface</hardwareInterface>
    </joint>
  </transmission>
  <transmission name="arm_left_4_trans">
    <type>transmission_interface/SimpleTransmission</type>
    <actuator name="arm_left_4_motor">
      <mechanicalReduction>1.0</mechanicalReduction>
    </actuator>
    <joint name="arm_left_4_joint">
      <offset>0.0</offset>
      <hardwareInterface>hardware_interface/PositionJointInterface</hardwareInterface>
      <hardwareInterface>hardware_interface/EffortJointInterface</hardwareInterface>
      <hardwareInterface>hardware_interface/JointStateInterface</hardwareInterface>
    </joint>
  </transmission>
  <!--First flexor-->
  <transmission name="hand_left_virtual_1_trans">
    <type>hey5_transmissions/Hey5Reducer</type>
    <joint name="hand_left_virtual_1_joint">
      <saturationLower>0.0</saturationLower>
      <deadBandUpper>0.0</deadBandUpper>
      <hardwareInterface>hardware_interface/JointStateInterface</hardwareInterface>
    </joint>
    <actuator name="hand_left_fingers_motor">
      <mechanicalReduction>1.0</mechanicalReduction>
    </actuator>
  </transmission>
  <!--Second flexor-->
  <transmission name="hand_left_virtual_2_trans">
    <type>hey5_transmissions/Hey5Reducer</type>
    <joint name="hand_left_virtual_2_joint">
      <saturationLower>0.0</saturationLower>
      <deadBandUpper>0.0</deadBandUpper>
      <hardwareInterface>hardware_interface/JointStateInterface</hardwareInterface>
    </joint>
    <actuator name="hand_left_fingers_motor">
      <mechanicalReduction>1.0</mechanicalReduction>
    </actuator>
  </transmission>
  <gazebo>
    <plugin filename="libgazebo_underactuated_finger.so" name="gazebo_left_fingers">
      <actuatedJoint>hand_left_fingers_joint</actuatedJoint>
      <virtualJoint>
        <name>hand_left_virtual_1_joint</name>
        <scale_factor>1.0</scale_factor>
      </virtualJoint>
      <virtualJoint>
        <name>hand_left_virtual_2_joint</name>
        <scale_factor>1.0</scale_factor>
      </virtualJoint>
    </plugin>
  </gazebo>
  <!--************************-->
  <!--      ARM_BASE_LINK     -->
  <!--************************-->
  <link name="arm_right_base_link">
    <inertial>
      <origin rpy="0 0 0" xyz="0.010252 -2.0895E-06 -0.010085"/>
      <mass value="0.41717"/>
      <inertia ixx="0.00020772" ixy="6.9296E-09" ixz="3.5124E-08" iyy="0.00033949" iyz="-5.2354E-09" izz="0.00046362"/>
    </inertial>
    <visual>
      <origin rpy="0 0 0" xyz="0 0 0"/>
      <geometry>
        <mesh filename="package://ari_description/meshes/arm/arm_base.stl" scale="1 -1 1"/>
      </geometry>
      <material name="Grey">
        <color rgba="0.29804 0.29804 0.29804 1"/>
      </material>
    </visual>
    <collision>
      <origin rpy="0 0 0" xyz="0 0 0"/>
      <geometry>
        <mesh filename="package://ari_description/meshes/arm/arm_base_collision.stl" scale="1 -1 1"/>
      </geometry>
    </collision>
  </link>
  <joint name="arm_right_base_joint" type="fixed">
    <origin rpy="-1.83259571459 0.0 3.14159265359" xyz="-0.219 -0.097624 1.1111"/>
    <child link="arm_right_base_link"/>
    <parent link="base_link"/>
  </joint>
  <!--************************-->
  <!--        SHOULDER        -->
  <!--************************-->
  <link name="arm_right_1_link">
    <inertial>
      <!--       <origin xyz="-0.012604 ${-0.00045914 * reflect} 0.082789" rpy="0.0 0.0 0.0"/> -->
      <origin rpy="0.0 0.0 0.0" xyz="-0.012773 0.00044 0.083205"/>
      <mass value="0.730376620707115"/>
      <inertia ixx="0.000883728615044291" ixy="-3.94329374494e-06" ixz="9.80047375813158E-05" iyy="0.000710081638353236" iyz="3.01812335433e-06" izz="0.000572003714116628"/>
    </inertial>
    <visual>
      <origin rpy="0 0 0" xyz="0 0 0"/>
      <geometry>
        <mesh filename="package://ari_description/meshes/arm/arm_1.stl" scale="1 -1 1"/>
      </geometry>
      <material name="White"/>
    </visual>
    <collision>
      <origin rpy="0 0 0" xyz="0 0 0"/>
      <geometry>
        <mesh filename="package://ari_description/meshes/arm/arm_1_collision.stl" scale="1 -1 1"/>
      </geometry>
    </collision>
  </link>
  <joint name="arm_right_1_joint" type="revolute">
    <parent link="arm_right_base_link"/>
    <child link="arm_right_1_link"/>
    <origin rpy="0.0 0.0 0.0" xyz="0.0 0.0 0.0"/>
    <axis xyz="0 0 1"/>
    <limit effort="10.0" lower="-2.09439510239" upper="2.09439510239" velocity="1.95"/>
    <dynamics damping="1.0" friction="1.0"/>
    <safety_controller k_position="20" k_velocity="20" soft_lower_limit="-2.02439510239" soft_upper_limit="2.02439510239"/>
  </joint>
  <link name="arm_right_2_link">
    <inertial>
      <origin rpy="0.0 0.0 0.0" xyz="0.0037554 0.0474088 0.01356828"/>
      <mass value="0.5891913"/>
      <inertia ixx="0.0006238" ixy="6.0701879e-06" ixz="9.3542493E-06" iyy="0.0005140" iyz="-9.8910641e-05" izz="0.0007757"/>
    </inertial>
    <visual>
      <origin rpy="0 0 0" xyz="0 0 0"/>
      <geometry>
        <mesh filename="package://ari_description/meshes/arm/arm_2.stl" scale="1 -1 1"/>
      </geometry>
      <material name="White"/>
    </visual>
    <collision>
      <origin rpy="0 0 0" xyz="0 0 0"/>
      <geometry>
        <mesh filename="package://ari_description/meshes/arm/arm_2_collision.stl" scale="1 -1 1"/>
      </geometry>
    </collision>
  </link>
  <joint name="arm_right_2_joint" type="revolute">
    <parent link="arm_right_1_link"/>
    <child link="arm_right_2_link"/>
    <origin rpy="1.5708 -1.8326 1.5708" xyz="-0.001 0 0.1145"/>
    <axis xyz="0 0 1"/>
    <limit effort="10.0" lower="-0.0872664625997" upper="2.70526034059" velocity="1.95"/>
    <dynamics damping="1.0" friction="1.0"/>
    <safety_controller k_position="20" k_velocity="20" soft_lower_limit="-0.0172664625997" soft_upper_limit="2.63526034059"/>
  </joint>
  <link name="arm_right_3_link">
    <inertial>
      <origin rpy="0.0 0.0 0.0" xyz="-0.0054056 0.0083079 0.06942"/>
      <mass value="0.4650332"/>
      <inertia ixx="0.0004078" ixy="-5.2043217e-05" ixz="3.12599823E-05" iyy="0.0004135" iyz="-2.6803484e-05" izz="0.0003238"/>
    </inertial>
    <visual>
      <origin rpy="0 0 0" xyz="0 0 0"/>
      <geometry>
        <mesh filename="package://ari_description/meshes/arm/arm_3.stl" scale="1 -1 1"/>
      </geometry>
      <material name="White"/>
    </visual>
    <collision>
      <origin rpy="0 0 0" xyz="0 0 0"/>
      <geometry>
        <mesh filename="package://ari_description/meshes/arm/arm_3_collision.stl" scale="1 -1 1"/>
      </geometry>
    </collision>
  </link>
  <joint name="arm_right_3_joint" type="revolute">
    <parent link="arm_right_2_link"/>
    <child link="arm_right_3_link"/>
    <origin rpy="1.57079632679 -0.785398163397 0.0" xyz="0.005 -0.10157 0.001"/>
    <axis xyz="0 0 1"/>
    <limit effort="5" lower="-2.09439510239" upper="2.09439510239" velocity="2.35"/>
    <dynamics damping="1.0" friction="1.0"/>
    <safety_controller k_position="20" k_velocity="20" soft_lower_limit="-2.02439510239" soft_upper_limit="2.02439510239"/>
  </joint>
  <!--************************-->
  <!--        ELBOW           -->
  <!--************************-->
  <link name="arm_right_4_link">
    <inertial>
      <origin rpy="0.0 0.0 0.0" xyz="0.0005502 -0.1185841 0.0184109"/>
      <mass value="0.5958179"/>
      <inertia ixx="0.00406585545706706" ixy="-0.000203216283995562" ixz="-8.35772941748004E-06" iyy="0.000334720111921714" iyz="-0.00015724504214636" izz="0.00422931703883722"/>
    </inertial>
    <visual>
      <origin rpy="0 0 0" xyz="0 0 0"/>
      <geometry>
        <mesh filename="package://ari_description/meshes/arm/arm_4.stl" scale="1 -1 1"/>
      </geometry>
      <material name="White"/>
    </visual>
    <collision>
      <origin rpy="0 0 0" xyz="0 0 0"/>
      <origin rpy="0 0 0" xyz="0 0 0"/>
      <geometry>
        <mesh filename="package://ari_description/meshes/arm/arm_4_collision.stl" scale="1 -1 1"/>
      </geometry>
    </collision>
  </link>
  <joint name="arm_right_4_joint" type="revolute">
    <parent link="arm_right_3_link"/>
    <child link="arm_right_4_link"/>
    <origin rpy="1.57079632679 0.0 0.785398163397" xyz="-0.0042426 0.0042426 0.1001"/>
    <axis xyz="0 0 1"/>
    <limit effort="5" lower="-0.0872664625997" upper="2.35619449019" velocity="2.35"/>
    <dynamics damping="1.0" friction="1.0"/>
    <safety_controller k_position="20" k_velocity="20" soft_lower_limit="-0.0172664625997" soft_upper_limit="2.28619449019"/>
  </joint>
  <!-- Tool Link -->
  <link name="arm_right_tool_link">
    <inertial>
      <origin rpy="0 0 0" xyz="0 0 0"/>
      <mass value="0.0001"/>
      <inertia ixx="0.00001" ixy="0.0" ixz="0.0" iyy="0.00001" iyz="0.0" izz="0.00001"/>
    </inertial>
  </link>
  <joint name="arm_right_tool_joint" type="fixed">
    <origin rpy="1.5708 -0.2618 -1.5708" xyz="0 0.35231 0.0011086"/>
    <parent link="arm_right_4_link"/>
    <child link="arm_right_tool_link"/>
    <axis xyz="0 0 0"/>
  </joint>
  <joint name="hand_right_fingers_joint" type="revolute">
    <parent link="arm_right_tool_link"/>
    <child link="hand_right_fingers_link"/>
    <origin rpy="0.0 0.0 0.0" xyz="0 0 0.0"/>
    <axis xyz="0 0 1"/>
    <limit effort="4.0" lower="0.0" upper="1.308996939" velocity="2.5"/>
    <dynamics damping="0.5" friction="0.0"/>
    <!-- TODO: Tune -->
    <safety_controller k_position="20" k_velocity="20" soft_lower_limit="0.0" soft_upper_limit="1.308996939"/>
  </joint>
  <link name="hand_right_fingers_link">
    <inertial>
      <origin rpy="0 0 0" xyz="0 0 0"/>
      <mass value="0.05"/>
      <inertia ixx="0.001" ixy="0" ixz="0" iyy="0.001" iyz="0" izz="0.001"/>
      <!--To stabilize simulation-->
    </inertial>
    <visual>
      <origin rpy="0 0 0" xyz="0 0 0"/>
      <geometry>
        <sphere radius="0.001"/>
      </geometry>
      <material name="White"/>
    </visual>
    <collision>
      <origin rpy="0 0 0" xyz="0 0 0"/>
      <geometry>
        <sphere radius="0.001"/>
      </geometry>
    </collision>
  </link>
  <transmission name="hand_right_fingers_trans">
    <type>transmission_interface/SimpleTransmission</type>
    <actuator name="hand_right_fingers_motor">
      <mechanicalReduction>1.0</mechanicalReduction>
    </actuator>
    <joint name="hand_right_fingers_joint">
      <hardwareInterface>hardware_interface/PositionJointInterface</hardwareInterface>
    </joint>
  </transmission>
  <link name="arm_right_grasping_frame"/>
  <joint name="arm_right_grasping_fixed_joint" type="fixed">
    <parent link="arm_right_4_link"/>
    <child link="arm_right_grasping_frame"/>
    <axis xyz="0 0 1"/>
    <origin rpy="1.5708 -0.2618 -1.5708" xyz="0 0.35231 0.0011086"/>
  </joint>
  <link name="hand_right_1_link">
    <inertial>
      <origin rpy="0 0 0" xyz="-0.0194858087119051 -0.00284946290069976 -0.000289044791174375"/>
      <mass value="0.0400715645648009"/>
      <inertia ixx="1.56769636746935E-06" ixy="2.22831013516217E-08" ixz="7.74537720537552E-09" iyy="4.6054803967178E-06" iyz="2.08251121489226E-10" izz="4.01623373583446E-06"/>
    </inertial>
    <visual>
      <origin rpy="0 0 0" xyz="0 0 0"/>
      <geometry>
        <mesh filename="package://ari_description/meshes/arm/hand_1.stl" scale="1 -1 1"/>
      </geometry>
      <material name="">
        <color rgba="0.752941176470588 0.752941176470588 0.752941176470588 1"/>
      </material>
    </visual>
    <collision>
      <origin rpy="0 0 0" xyz="0 0 0"/>
      <geometry>
        <mesh filename="package://ari_description/meshes/arm/hand_1_collision.stl" scale="1 -1 1"/>
      </geometry>
    </collision>
  </link>
  <joint name="hand_right_virtual_1_joint" type="revolute">
    <origin rpy="1.5708 -0.2618 -1.5708" xyz="0 0.35231 0.0011086"/>
    <parent link="arm_right_4_link"/>
    <child link="hand_right_1_link"/>
    <axis xyz="0 0 1"/>
    <limit effort="1.0" lower="0" upper="1.35" velocity="2.0"/>
    <!--
      <dynamics friction="${arm_friction}" damping="${arm_damping}"/>
      <safety_controller k_position="20"
                           k_velocity="20"
                           soft_lower_limit="${0.0 + arm_eps}"
                           soft_upper_limit="${1.5708 - arm_eps}" />
  -->
  </joint>
  <link name="hand_right_2_link">
    <inertial>
      <origin rpy="0 0 0" xyz="-0.0159508701186225 0.00214676466101674 0.000361575914240066"/>
      <mass value="0.0262043707272721"/>
      <inertia ixx="9.15137557050205E-07" ixy="5.3927377524493E-07" ixz="-5.3325168061876E-09" iyy="2.67374552400975E-06" iyz="-6.4411286354103E-10" izz="2.38630247657937E-06"/>
    </inertial>
    <visual>
      <origin rpy="0 0 0" xyz="0 0 0"/>
      <geometry>
        <mesh filename="package://ari_description/meshes/arm/hand_2.stl" scale="1 -1 1"/>
      </geometry>
      <material name="">
        <color rgba="0.752941176470588 0.752941176470588 0.752941176470588 1"/>
      </material>
    </visual>
    <collision>
      <origin rpy="0 0 0" xyz="0 0 0"/>
      <geometry>
        <mesh filename="package://ari_description/meshes/arm/hand_2_collision.stl" scale="1 -1 1"/>
      </geometry>
    </collision>
  </link>
  <joint name="hand_right_virtual_2_joint" type="revolute">
    <origin rpy="0 0 0" xyz="-0.037185 0.0001459 0"/>
    <parent link="hand_right_1_link"/>
    <child link="hand_right_2_link"/>
    <axis xyz="0 0 1"/>
    <limit effort="1.0" lower="0" upper="1.5708" velocity="2.0"/>
    <!--
      <dynamics friction="${arm_friction}" damping="${arm_damping}"/>
      <safety_controller k_position="20"
                           k_velocity="20"
                           soft_lower_limit="${0.0 + arm_eps}"
                           soft_upper_limit="${1.5708 - arm_eps}" />
  -->
  </joint>
  <gazebo reference="arm_right_1_link">
    <mu1>0.9</mu1>
    <mu2>0.9</mu2>
    <material>Gazebo/DarkGrey</material>
  </gazebo>
  <gazebo reference="arm_right_2_link">
    <mu1>0.9</mu1>
    <mu2>0.9</mu2>
    <material>Gazebo/DarkGrey</material>
  </gazebo>
  <gazebo reference="arm_right_3_link">
    <mu1>0.9</mu1>
    <mu2>0.9</mu2>
    <material>Gazebo/DarkGrey</material>
  </gazebo>
  <gazebo reference="arm_right_4_link">
    <mu1>0.9</mu1>
    <mu2>0.9</mu2>
    <material>Gazebo/DarkGrey</material>
  </gazebo>
  <gazebo reference="hand_right_1_link">
    <mu1>0.9</mu1>
    <mu2>0.9</mu2>
    <material>Gazebo/DarkGrey</material>
  </gazebo>
  <gazebo reference="hand_right_2_link">
    <mu1>0.9</mu1>
    <mu2>0.9</mu2>
    <material>Gazebo/DarkGrey</material>
  </gazebo>
  <gazebo reference="arm_right_1_joint">
    <implicitSpringDamper>1</implicitSpringDamper>
  </gazebo>
  <gazebo reference="arm_right_2_joint">
    <implicitSpringDamper>1</implicitSpringDamper>
  </gazebo>
  <gazebo reference="arm_right_3_joint">
    <implicitSpringDamper>1</implicitSpringDamper>
  </gazebo>
  <gazebo reference="arm_right_4_joint">
    <implicitSpringDamper>1</implicitSpringDamper>
  </gazebo>
  <gazebo reference="hand_right_virtual_1_joint">
    <implicitSpringDamper>1</implicitSpringDamper>
  </gazebo>
  <gazebo reference="hand_right_virtual_2_joint">
    <implicitSpringDamper>1</implicitSpringDamper>
  </gazebo>
  <transmission name="arm_right_1_trans">
    <type>transmission_interface/SimpleTransmission</type>
    <actuator name="arm_right_1_motor">
      <mechanicalReduction>1.0</mechanicalReduction>
    </actuator>
    <joint name="arm_right_1_joint">
      <offset>0.0</offset>
      <hardwareInterface>hardware_interface/PositionJointInterface</hardwareInterface>
      <hardwareInterface>hardware_interface/EffortJointInterface</hardwareInterface>
      <hardwareInterface>hardware_interface/JointStateInterface</hardwareInterface>
    </joint>
  </transmission>
  <transmission name="arm_right_2_trans">
    <type>transmission_interface/SimpleTransmission</type>
    <actuator name="arm_right_2_motor">
      <mechanicalReduction>1.0</mechanicalReduction>
    </actuator>
    <joint name="arm_right_2_joint">
      <offset>0.0</offset>
      <hardwareInterface>hardware_interface/PositionJointInterface</hardwareInterface>
      <hardwareInterface>hardware_interface/EffortJointInterface</hardwareInterface>
      <hardwareInterface>hardware_interface/JointStateInterface</hardwareInterface>
    </joint>
  </transmission>
  <transmission name="arm_right_3_trans">
    <type>transmission_interface/SimpleTransmission</type>
    <actuator name="arm_right_3_motor">
      <mechanicalReduction>1.0</mechanicalReduction>
    </actuator>
    <joint name="arm_right_3_joint">
      <offset>0.0</offset>
      <hardwareInterface>hardware_interface/PositionJointInterface</hardwareInterface>
      <hardwareInterface>hardware_interface/EffortJointInterface</hardwareInterface>
      <hardwareInterface>hardware_interface/JointStateInterface</hardwareInterface>
    </joint>
  </transmission>
  <transmission name="arm_right_4_trans">
    <type>transmission_interface/SimpleTransmission</type>
    <actuator name="arm_right_4_motor">
      <mechanicalReduction>1.0</mechanicalReduction>
    </actuator>
    <joint name="arm_right_4_joint">
      <offset>0.0</offset>
      <hardwareInterface>hardware_interface/PositionJointInterface</hardwareInterface>
      <hardwareInterface>hardware_interface/EffortJointInterface</hardwareInterface>
      <hardwareInterface>hardware_interface/JointStateInterface</hardwareInterface>
    </joint>
  </transmission>
  <!--First flexor-->
  <transmission name="hand_right_virtual_1_trans">
    <type>hey5_transmissions/Hey5Reducer</type>
    <joint name="hand_right_virtual_1_joint">
      <saturationLower>0.0</saturationLower>
      <deadBandUpper>0.0</deadBandUpper>
      <hardwareInterface>hardware_interface/JointStateInterface</hardwareInterface>
    </joint>
    <actuator name="hand_right_fingers_motor">
      <mechanicalReduction>1.0</mechanicalReduction>
    </actuator>
  </transmission>
  <!--Second flexor-->
  <transmission name="hand_right_virtual_2_trans">
    <type>hey5_transmissions/Hey5Reducer</type>
    <joint name="hand_right_virtual_2_joint">
      <saturationLower>0.0</saturationLower>
      <deadBandUpper>0.0</deadBandUpper>
      <hardwareInterface>hardware_interface/JointStateInterface</hardwareInterface>
    </joint>
    <actuator name="hand_right_fingers_motor">
      <mechanicalReduction>1.0</mechanicalReduction>
    </actuator>
  </transmission>
  <gazebo>
    <plugin filename="libgazebo_underactuated_finger.so" name="gazebo_right_fingers">
      <actuatedJoint>hand_right_fingers_joint</actuatedJoint>
      <virtualJoint>
        <name>hand_right_virtual_1_joint</name>
        <scale_factor>1.0</scale_factor>
      </virtualJoint>
      <virtualJoint>
        <name>hand_right_virtual_2_joint</name>
        <scale_factor>1.0</scale_factor>
      </virtualJoint>
    </plugin>
  </gazebo>
</robot>

